<!doctype html>
<html>
	<head>
		<meta charset="utf-8">
		<meta name="viewport" content="width=device-width, initial-scale=1.0, maximum-scale=1.0, user-scalable=no">

		<title>Programmieren 2 - Kapitel 2 - Exception-Handling</title>

		<link rel="stylesheet" href="reveal.js/dist/reset.css">
		<link rel="stylesheet" href="reveal.js/dist/reveal.css">

        <link rel="stylesheet" href="src/slides.css">
        <link rel="stylesheet" href="src/style.css">

		<link rel="stylesheet" href="src/layout.css">
        <link rel="stylesheet" href="lib/joint.min.css" />
        <link rel="stylesheet" href="src/erd.css" />
        <link rel="stylesheet" href="src/poll.css" />

		<!-- Theme used for syntax highlighting of code -->
		<script>
			if(window.location.search.match( /print-pdf/gi )) {
				document.getElementsByTagName( "head" )[0].innerHTML += '<link rel="stylesheet" href="src/routeros.css">';
			} else {
				document.getElementsByTagName( "head" )[0].innerHTML += '<link rel="stylesheet" href="src/rainbow.css">';
			}
			</script>
        <!--<script defer src="lib/fontawesome.all.min.js"/>-->
        <link href="lib/fontawesome.all.min.css" rel="stylesheet">
        <style> .reveal i.fa { font-family:FontAwesome; font-style: normal; } </style>
	</head>
	<body>
		<div class="reveal">
            <div id="header"></div>
            <div id="footer"></div>
			<div class="slides">
                <section>
                    <h4 style="text-align:center"><b>Prof. Dr.-Ing. Johannes Schildgen</b><br>
                    <a href="mailto:johannes.schildgen@h-da.de">johannes.schildgen@oth-regensburg.de</a></h4>
                    <h1 style="font-size: 200%; margin-top: 1.5cm;">Programmieren 2 (Python)</h1>
                    <h3>Kapitel 3: Exception-Handling</h3>
                    <h4 style="text-align:center">&nbsp;</h4>
                    <img src="img/ccby.png" height="60px" style="position: absolute; left:0px; border:0; bottom:-225px;">
                    <img src="img/oth.png" height="60px" style="position: absolute; right:0px; border:0; bottom:-225px; box-shadow:none">
                </section>
                
                <section>
                  <h2>Exceptions</h2>
                  <div class="trackinfo"><i class="fas fa-book"></i> 10</div>
                  <p class="small">Exceptions werden geworfen, wenn eine Ausnahmesituation auftritt.</p>
                  <pre style="width: 95%;"><code class="python" contenteditable data-sample='code/3/valueerror.py'></code></pre>
                  <p class="fragment small red">Traceback (most recent call last):<br>
                    &nbsp;&nbsp;File "meinprogramm.py", line 3, in &lt;module&gt;<br>
                    &nbsp;&nbsp;&nbsp;&nbsp;anzahl = int(anzahl_str)<br>
                  ValueError: invalid literal for int() with base 10: 'ganz viele'</p>

                  <pre class="fragment" style="width: 95%;"><code class="python" contenteditable data-sample='code/3/indexerror.py'></code></pre>
                  <p class="fragment small red">IndexError: list index out of range</p>
                  
                  
                  <aside class="notes">Im obigen Beispiel ist die <code>int</code>-Funktion aufgrund ungültiger Zeichen (&quot;ganz viele&quot;) nicht in der Lage, den String in eine Zahl zu wandeln. Daher wirft die Funktion einen <code>ValueError</code>. Im zweiten Beispiel geht der Index in der Liste <code>l</code> von 0 bis 2. Der Zugriff auf <code>l[3]</code> wirft deshalb die Exception.</aside>
                </section>
                
                <section>
                  <h3>Catch or Throw</h3>
                  <p class="small">Wenn Exceptions auftreten, hat man zwei Möglichkeiten, diese zu behandeln:</p>
                  <ol class="small">
                    <li>Exception auffangen (<code>try: ... except: ...</code>)<br>Was soll getan werden, wenn die Exception auftritt?<br>&nbsp;</li>
                    <li>Exception weiterwerfen (Standardverhalten)<br>Der, der mich aufgerufen hat, bekommt die Exception zu Gesicht<br>&nbsp;</li>
                  </ol>

                  <h4><code>try</code></h4>
                  <pre style="width: 95%;"><code class="python" data-sample-indent="keep" data-sample='code/3/try.py'></code></pre>
                  <aside class="notes">In den beiden Beispielen auf der vorherigen Folie wurden die Exceptions, die zur Laufzeit auftreten können, einfach weitergeworfen. Das Beispiel hier fängt den <code>ValueError</code> ab, sodass das Programm weiterlaufen kann, auch wenn der Fehler auftritt.</aside>
                </section>

                <section>
                  <h3><code>try: ... except ...: ...</code></h3>
                  <div class="trackinfo"><i class="fas fa-book"></i> 10.1</div>
                  <p class="small">Tritt zur Laufzeit innerhalb des <code>try</code>-Blocks die unter <code>except</code> genannte Exception auf, wird sofort in ebendiesen <code>except</code>-Block gesprungen.</p>
                  <pre style="width: 98%;"><code class="python" data-sample-indent="keep" data-sample='code/3/try_loop.py'></code></pre>
                  <aside class="notes">Ohne <code>try</code> würde unser Programm abstürzen, wenn der Benutzer einen ungültigen Wert eingibt. Nun wird er oder sie einfach so oft erneut gefragt, eine Zahl einzugeben, bis es eine gültige Zahl ist. Wird ein ungültiger Wert eingegeben, tritt in Zeile 4 (<code>int</code>-Funktion) ein <code>ValueError</code> auf. Dieser wird in Zeile 6 (<code>except</code>) abgefangen. Das Programm springt also sofort von Zeile 4 in Zeile 7.</aside>
                </section>

                <section>
                  <h2>Übung 3.1</h2>
                  <div style="position: absolute; top:1mm; right: 1mm; font-weight: bold; font-size: 150%; color:#b9a93e"><countdown time="540" autostart="no" /></div>
                    <p class="small">Entwickeln Sie einen Taschenrechner, der den Benutzer bittet, zwei Zahlen einzugeben, und daraufhin den Quotienten der Zahl ausgibt. Fangen Sie mit <code>try</code> sowohl den Fall ab, dass ungültige Zahlen eingegeben werden, als auch ein Teilen durch 0. Eine ungültige Zahl soll als eine 0 behandelt werden. Wird durch 0 geteilt, soll eine entsprechende Meldung ausgegeben werden.<br>&nbsp;</p>
                </section>

                <section>
                  <h3>Abfangen verschiedener Exceptions</h3>
                  <div class="trackinfo"><i class="fas fa-book"></i> 10.1</div>
                  <pre style="width: 98%;"><code style="min-height: 10.7cm;" class="python" data-sample-indent="keep" data-sample='code/3/try_mehrere.py'></code></pre>
                  <p class="small">Hier wurden Exceptions mittels <code>as err</code> einen Namen gegeben. Informationen zur Exception stehen nun in der Variable <code>err</code> zur Verfügung.</p>
                </section>

                <section>
                  <h3>Typische Exceptions</h3>
                  <div class="trackinfo"><i class="fas fa-book"></i> 10.1</div>
                  <div style="position: absolute; top:13cm; right: 1mm; font-weight: bold; font-size: 150%; color:#b9a93e"><countdown time="600" autostart="no" /></div>
                  <ul class="small">
                    <li><code>FileNotFoundException</code> - Datei existiert nicht</li>
                    <li><code>IndexError</code> - Die angegebene Position in Liste oder String gibt es nicht</li>
                    <li><code>KeyError</code> - Der Schlüssel existiert nicht im Dictionary</li>
                    <li><code>KeyboardInterrupt</code> - Anwender hat Strg+C gedrückt (z. B. bei <code>input</code>)</li>
                    <li><code>NameError</code> - Variable, Funktion, etc. gibt es nicht</li>
                    <li><code>PermissionError</code> - Rechte für den Dateizugriff fehlen</li>
                    <li><code>RecursionError</code> - Zu hohe Rekursionstiefe erreicht</li>
                    <li><code>TypeError</code> - Falscher Datentyp (z. B. <code>3 + "hi"</code>)</li>
                    <li><code>ValueError</code> - Wert ist nicht gültig (z. B. <code>int("hallo"))</code></li>
                    <li><code>ZeroDivisionError</code> - Division durch 0</li>
                  </ul>

                  <p class="small"></p>
                  <h4>Übung 3.2</h4>
                  <p class="small">Erzeugen Sie auf der interaktiven Python-Konsole oder in einzelnen Python-Scripts einmal jede dieser Exceptions.</p>
                </section>

                <section>
                  <h3><code>finally</code></h3>
                  <div class="trackinfo"><i class="fas fa-book"></i> 10.1</div>
                  <p class="small">Der <code>finally</code>-Block wird in jedem Falle aufgerufen, egal ob der <code>try</code>-Block mit oder ohne Exception durchlaufen wurde.</p>
                  <pre style="width: 98%;"><code class="python" data-sample-indent="keep" data-sample='code/3/finally.py'></code></pre>
                  <p class="small"><code>locals()</code> liefert ein Dictionary mit allen lokalen Variablen.</p>
                  <aside class="notes">Der <code>finally</code>-Block wird selbst dann noch aufgerufen, wenn im <code>try</code>-Block die Methode, Schleife, etc. mit <code>return</code>, <code>break</code> oder <code>continue</code> verlassen wurde. Ein typischer Anwendungsfall für <code>finally</code> ist es, Aufräumarbeiten durchzuführen, also Dateien oder Verbindungen zu schließen. Im Beispiel wurde auch <code>pass</code> verwendet. Der Fehler wird also einfach ignoriert und es wird nichts gemacht, wenn die Datei nicht gefunden wurde.</aside>
                </section>

                <section>
                  <h3><code>with ... as</code></h3>
                  <div class="trackinfo"><i class="fas fa-book"></i> 14.2</div>
                  <p class="small"><code>with ... as</code> öffnet eine Ressource, die nach Beendigung des <code>with</code>-Blocks von Python automatisch wieder geschlossen wird. Dies ist der empfohlene Weg.</p>
                  <pre style="width: 98%;"><code class="python" data-sample-indent="keep" data-sample='code/3/with.py#with'></code></pre>
                  <p class="small">In Kombination mit <code>try:</code></p>
                  <pre style="width: 98%;"><code class="python" data-sample-indent="keep" data-sample='code/3/with.py#try'></code></pre>
                  <aside class="notes">Bei der Verwendung von <code>with</code> muss man sich nicht um das Schließen der Ressourcen (hier: Datei) kümmern und man braucht kein <code>finally</code>. Python ruft nach Beendigung des Blocks die <code>__exit__</code>-Methode auf der angegebenen Variable auf, die in unserem Fall für <code>f.close()</code> sorgt.</aside>
                </section>

                <section>
                  <h2>Übung 3.3</h2>
                  <div style="position: absolute; top:1mm; right: 1mm; font-weight: bold; font-size: 150%; color:#b9a93e"><countdown time="720" autostart="no" /></div>
                    <ol class="small">
                      <li>Legen Sie eine Datei zahl.txt an, in der eine Zahl steht, z. B. 5. Entwickeln Sie dann ein Python-Programm, welches die Datei öffnet und so oft Hallo ausgibt, wie es in der Datei steht (bei 5 also fünf mal). Kümmern Sie sich zunächst nicht um Exceptions.</li>
                      <li>Erweitern Sie Ihr Programm so, dass der Benutzer gefragt wird, einen Dateinamen einzugeben. Und zwar so lange, bis die entsprechende Datei auch wirklich existiert und geöffnet werden kann.</li>
                      <li>Steht in der Datei keine ganze positive Zahl, soll einfach nur 1x Hallo ausgegeben werden.</li>
                </section>

                <section>
                  <h3>Exception weiter werfen</h3>
                  <p class="small">Werden Exceptions mit <code>try</code> nicht abgefangen, werden sie nach außen weitergeworfen. Ganz außen angekommen? Programm beendet sich mit Fehler.</p>
                  <div class="columns">
                    <div><pre style="width: 13.5cm;"><code class="python" data-sample-indent="keep" data-sample='code/3/weiterwerfen.py'></code></pre></div>
                    <div style="margin-left: 3mm;"><p class="red" style="font-size: 63%;">Traceback (most recent call last):
                      <br>&nbsp;&nbsp;File "meinprogramm.py", line 9, in <module>
                      <br>&nbsp;&nbsp;&nbsp;&nbsp;print(durchschnitt(leer))
                      <br>&nbsp;&nbsp;File "meinprogramm.py", line 5, in durchschnitt
                      <br>&nbsp;&nbsp;&nbsp;&nbsp;return teilen(sum(l), len(l))
                      <br>&nbsp;&nbsp;File "meinprogramm.py", line 2, in teilen
                      <br>&nbsp;&nbsp;&nbsp;&nbsp;return a/b
                    <br>ZeroDivisionError: division by zero</p></div>
                  </div>

                  <aside class="notes">Im Hauptteil des Scriptes (letzte Zeile) tritt der Fehler auf. Dort wird versucht, den Durchschnitt aus 0 Zahlen in einer leeren Liste zu berechnen. Da weder in der <code>teilen</code>-Funktion die Division durch 0 abgefangen wurde, noch in der Funktion <code>durchschnitt</code> und auch nicht beim Aufruf der <code>durchschnitt</code>-Funktion im main-Teil, wird die Exception immer weitergereicht zu der Stelle, an der die aktuelle Funktion aufgerufen wird. In der Fehlermeldung sieht man den kompletten Stacktrace. Wenn man ihn von unten nach oben liest, sieht man sofort die Stelle, die letztendlich für den Fehler gesorgt hat.</aside>
                </section>

                <section>
                  <h3><code>raise</code> - Selbst Exceptions werfen</h3>
                  <div class="trackinfo"><i class="fas fa-book"></i> 10.2</div>
                  <pre style="width: 98%; margin-top: -3mm;"><code class="python" data-sample-indent="keep" data-sample='code/3/raise.py'></code></pre>
                  <p class="small red" style="margin-top: -3mm;">ValueError: Ungültiges Passwort</p>
                  <pre style="width: 98%;"><code class="python" data-sample-indent="keep" data-sample='code/3/raise_try.py#main'></code></pre>
                  <aside class="notes">Unsere Funktion <code>stars</code> wirft nun eine Exception, wenn man sie mit einem zu kurzen Passwort aufruft. Beim Werfen von Exceptions kann man sich einer passenden Exception (hier ValueError) bedienen. Alternativ kann man auch eigene Exception-Klassen entwickeln (siehe Kapitel über Objektorientierung).</aside>
                </section>

                <section>
                  <h2>Übung 3.4</h2>
                  <div style="position: absolute; top:1mm; right: 1mm; font-weight: bold; font-size: 150%; color:#b9a93e"><countdown time="720" autostart="no" /></div>
                    <ol class="small">
                      <li>Schreiben Sie eine Funktion <code>f(a,b,c)</code>, die die Summe der drei übergebenen Zahlen ausgibt. Sollte eine der Zahlen <code>None</code> sein, soll eine Exception geworfen werden.<br>&nbsp;</li>
                      <li>Schreiben Sie eine Funktion <code>fakultaet(x)</code>, die $x!$ berechnet. Werfen Sie eine entsprechende Exception, wenn der Funktion ungültige Werte übergeben werden (-1, 1.5, "Hallo", ...).</li>
                </section>

                <section>
                  <h2>Kapitelzusammenfassung</h2>
                  <ul>
                    <li>Exceptions</li>
                    <li><code>try: ... except ...: ...</code></li>
                    <li><code>try: ... finally: ...</code></li>
                    <li><code>with ... as ...:</code></li>
                    <li><code>raise</code></li>
                  </ul>
          </section>

              </div>
            </div>
        
            <script src="reveal.js/dist/reveal.js"></script>
		<script src="reveal.js/plugin/markdown/markdown.js"></script>
		<script src="reveal.js/plugin/highlight/highlight.js"></script>
		<script src="reveal.js/plugin/zoom/zoom.js"></script>
		<script src="reveal.js/plugin/math/math.js"></script>
		<script src="reveal.js/plugin/notes/notes.js"></script>
		<script src="reveal.js/plugin/search/search.js"></script>
        <script src="lib/jquery.js"></script>
        <script src="lib/lodash.js"></script>
        <script src="lib/backbone.js"></script>
        <script src="lib/joint.min.js"></script>
				<script src="lib/deflate.js"></script>

		<script src="src/init_reveal.js"></script>

        <script>
        if(window.location.search.match( /print-pdf/gi )) {
                document.getElementById('header').style="display:none";
                document.getElementById('footer').style="display:none";
        }
        </script>

        
        
          </body>
        </html>
        